<?xml version="1.0" ?>
<!-- =================================================================================== -->
<!-- |    This document was autogenerated by xacro from robot_core.urdf.xacro          | -->
<!-- |    EDITING THIS FILE BY HAND IS NOT RECOMMENDED                                 | -->
<!-- =================================================================================== -->
<robot name="frbot">
  <material name="dark_grey">
    <color rgba="0.2 0.2 0.2 1.0"/>
  </material>
  <material name="light_grey">
    <color rgba="0.4 0.4 0.4 1.0"/>
  </material>
  <material name="yellow">
    <color rgba="0.8 0.8 0.0 1.0"/>
  </material>
  <material name="black">
    <color rgba="0.15 0.15 0.15 1.0"/>
  </material>

  <link name="base_link"/>
  <joint name="base_link_joint" type="fixed">
    <origin rpy="0 0 0" xyz="0 0 0"/>
    <parent link="base_link"/>
    <child link="chassis_link"/>
  </joint>

  <link name="chassis_link">
    <visual>
      <origin rpy="1.57079632679 0 1.57079632679" xyz="0 0 -0.0655"/>
      <geometry>
        <mesh filename="file://$(find frbot_description)/meshes/jackal-base.stl"/>
      </geometry>
      <material name="dark_grey"/>
    </visual>
    <collision>
      <origin xyz="0 0 0.092"/>
      <geometry>
        <box size="0.42 0.31 0.184"/>
      </geometry>
    </collision>
    <inertial>
      <!-- Center of mass -->
      <origin rpy="0 0 0" xyz="0.012  0.002 0.067"/>
      <mass value="16.523"/>
      <!-- Moments of inertia: ( chassis without wheels ) -->
      <inertia ixx="0.3136" ixy="-0.0008" ixz="0.0164" iyy="0.3922" iyz="-0.0009" izz="0.4485"/>
    </inertial>
  </link>

  <link name="front_fender_link">
    <visual>
      <geometry>
        <mesh filename="file://$(find frbot_description)/meshes/jackal-fender.stl"/>
      </geometry>
      <material name="yellow"/>
    </visual>
  </link>

  <joint name="front_fender_joint" type="fixed">
    <origin rpy="0 0 0" xyz="0 0 0"/>
    <parent link="chassis_link"/>
    <child link="front_fender_link"/>
  </joint>
  <link name="rear_fender_link">
    <visual>
      <geometry>
        <mesh filename="file://$(find frbot_description)/meshes/jackal-fender.stl"/>
      </geometry>
      <material name="yellow"/>
    </visual>
  </link>

  <joint name="rear_fender_joint" type="fixed">
    <origin rpy="0 0 3.14159265359" xyz="0 0 0"/>
    <parent link="chassis_link"/>
    <child link="rear_fender_link"/>
  </joint>

  <link name="front_left_wheel_link">
    <visual>
      <origin rpy="1.57079632679 0 0" xyz="0 0 0"/>
      <geometry>
        <mesh filename="file://$(find frbot_description)/meshes/jackal-wheel.stl"/>
      </geometry>
      <material name="black"/>
    </visual>
    <collision>
      <origin rpy="1.57079632679 0 0" xyz="0 0 0"/>
      <geometry>
        <cylinder length="0.04" radius="0.098"/>
      </geometry>
    </collision>
    <inertial>
      <origin rpy="0 0 0" xyz="0 0 0"/>
      <mass value="0.477"/>
      <inertia ixx="0.0013" ixy="0" ixz="0" iyy="0.0024" iyz="0" izz="0.0013"/>
    </inertial>
  </link>

  <joint name="front_left_wheel_joint" type="continuous">
    <parent link="chassis_link"/>
    <child link="front_left_wheel_link"/>
    <origin rpy="0 0 0" xyz="0.131 0.187795 0.0345"/>
    <axis xyz="0 1 0"/>
  </joint>
  
  <link name="front_right_wheel_link">
    <visual>
      <origin rpy="1.57079632679 0 0" xyz="0 0 0"/>
      <geometry>
        <mesh filename="file://$(find frbot_description)/meshes/jackal-wheel.stl"/>
      </geometry>
      <material name="black"/>
    </visual>
    <collision>
      <origin rpy="1.57079632679 0 0" xyz="0 0 0"/>
      <geometry>
        <cylinder length="0.04" radius="0.098"/>
      </geometry>
    </collision>
    <inertial>
      <origin rpy="0 0 0" xyz="0 0 0"/>
      <mass value="0.477"/>
      <inertia ixx="0.0013" ixy="0" ixz="0" iyy="0.0024" iyz="0" izz="0.0013"/>
    </inertial>
  </link>
  <joint name="front_right_wheel_joint" type="continuous">
    <parent link="chassis_link"/>
    <child link="front_right_wheel_link"/>
    <origin rpy="0 0 0" xyz="0.131 -0.187795 0.0345"/>
    <axis xyz="0 1 0"/>
  </joint>
  <link name="rear_left_wheel_link">
    <visual>
      <origin rpy="1.57079632679 0 0" xyz="0 0 0"/>
      <geometry>
        <mesh filename="file://$(find frbot_description)/meshes/jackal-wheel.stl"/>
      </geometry>
      <material name="black"/>
    </visual>
    <collision>
      <origin rpy="1.57079632679 0 0" xyz="0 0 0"/>
      <geometry>
        <cylinder length="0.04" radius="0.098"/>
      </geometry>
    </collision>
    <inertial>
      <origin rpy="0 0 0" xyz="0 0 0"/>
      <mass value="0.477"/>
      <inertia ixx="0.0013" ixy="0" ixz="0" iyy="0.0024" iyz="0" izz="0.0013"/>
    </inertial>
  </link>
  <joint name="rear_left_wheel_joint" type="continuous">
    <parent link="chassis_link"/>
    <child link="rear_left_wheel_link"/>
    <origin rpy="0 0 0" xyz="-0.131 0.187795 0.0345"/>
    <axis xyz="0 1 0"/>
  </joint>
  <link name="rear_right_wheel_link">
    <visual>
      <origin rpy="1.57079632679 0 0" xyz="0 0 0"/>
      <geometry>
        <mesh filename="file://$(find frbot_description)/meshes/jackal-wheel.stl"/>
      </geometry>
      <material name="black"/>
    </visual>
    <collision>
      <origin rpy="1.57079632679 0 0" xyz="0 0 0"/>
      <geometry>
        <cylinder length="0.04" radius="0.098"/>
      </geometry>
    </collision>
    <inertial>
      <origin rpy="0 0 0" xyz="0 0 0"/>
      <mass value="0.477"/>
      <inertia ixx="0.0013" ixy="0" ixz="0" iyy="0.0024" iyz="0" izz="0.0013"/>
    </inertial>
  </link>
  <joint name="rear_right_wheel_joint" type="continuous">
    <parent link="chassis_link"/>
    <child link="rear_right_wheel_link"/>
    <origin rpy="0 0 0" xyz="-0.131 -0.187795 0.0345"/>
    <axis xyz="0 1 0"/>
  </joint>
</robot>
